WARNING:root:Failed to download from `https://omnipathdb.org/`.
WARNING:root:Traceback (most recent call last):
  File "/home/aih/sebastian.birk/miniconda3/envs/nichecompass/lib/python3.9/site-packages/urllib3/connection.py", line 174, in _new_conn
    conn = connection.create_connection(
  File "/home/aih/sebastian.birk/miniconda3/envs/nichecompass/lib/python3.9/site-packages/urllib3/util/connection.py", line 95, in create_connection
    raise err
  File "/home/aih/sebastian.birk/miniconda3/envs/nichecompass/lib/python3.9/site-packages/urllib3/util/connection.py", line 85, in create_connection
    sock.connect(sa)
socket.timeout: timed out

During handling of the above exception, another exception occurred:

Traceback (most recent call last):
  File "/home/aih/sebastian.birk/miniconda3/envs/nichecompass/lib/python3.9/site-packages/urllib3/connectionpool.py", line 715, in urlopen
    httplib_response = self._make_request(
  File "/home/aih/sebastian.birk/miniconda3/envs/nichecompass/lib/python3.9/site-packages/urllib3/connectionpool.py", line 404, in _make_request
    self._validate_conn(conn)
  File "/home/aih/sebastian.birk/miniconda3/envs/nichecompass/lib/python3.9/site-packages/urllib3/connectionpool.py", line 1058, in _validate_conn
    conn.connect()
  File "/home/aih/sebastian.birk/miniconda3/envs/nichecompass/lib/python3.9/site-packages/urllib3/connection.py", line 363, in connect
    self.sock = conn = self._new_conn()
  File "/home/aih/sebastian.birk/miniconda3/envs/nichecompass/lib/python3.9/site-packages/urllib3/connection.py", line 179, in _new_conn
    raise ConnectTimeoutError(
urllib3.exceptions.ConnectTimeoutError: (<urllib3.connection.HTTPSConnection object at 0x7f5755b97a60>, 'Connection to omnipathdb.org timed out. (connect timeout=3.0)')

During handling of the above exception, another exception occurred:

Traceback (most recent call last):
  File "/home/aih/sebastian.birk/miniconda3/envs/nichecompass/lib/python3.9/site-packages/requests/adapters.py", line 486, in send
    resp = conn.urlopen(
  File "/home/aih/sebastian.birk/miniconda3/envs/nichecompass/lib/python3.9/site-packages/urllib3/connectionpool.py", line 799, in urlopen
    retries = retries.increment(
  File "/home/aih/sebastian.birk/miniconda3/envs/nichecompass/lib/python3.9/site-packages/urllib3/util/retry.py", line 592, in increment
    raise MaxRetryError(_pool, url, error or ResponseError(cause))
urllib3.exceptions.MaxRetryError: HTTPSConnectionPool(host='omnipathdb.org', port=443): Max retries exceeded with url: /queries/enzsub?format=json (Caused by ConnectTimeoutError(<urllib3.connection.HTTPSConnection object at 0x7f5755b97a60>, 'Connection to omnipathdb.org timed out. (connect timeout=3.0)'))

During handling of the above exception, another exception occurred:

Traceback (most recent call last):
  File "/home/aih/sebastian.birk/miniconda3/envs/nichecompass/lib/python3.9/site-packages/omnipath/_core/downloader/_downloader.py", line 143, in maybe_download
    res = self._download(req)
  File "/home/aih/sebastian.birk/miniconda3/envs/nichecompass/lib/python3.9/site-packages/omnipath/_core/downloader/_downloader.py", line 178, in _download
    with self._session.send(
  File "/home/aih/sebastian.birk/miniconda3/envs/nichecompass/lib/python3.9/site-packages/requests/sessions.py", line 703, in send
    r = adapter.send(request, **kwargs)
  File "/home/aih/sebastian.birk/miniconda3/envs/nichecompass/lib/python3.9/site-packages/requests/adapters.py", line 507, in send
    raise ConnectTimeout(e, request=request)
requests.exceptions.ConnectTimeout: HTTPSConnectionPool(host='omnipathdb.org', port=443): Max retries exceeded with url: /queries/enzsub?format=json (Caused by ConnectTimeoutError(<urllib3.connection.HTTPSConnection object at 0x7f5755b97a60>, 'Connection to omnipathdb.org timed out. (connect timeout=3.0)'))

/home/aih/sebastian.birk/miniconda3/envs/nichecompass/lib/python3.9/site-packages/dask/dataframe/_pyarrow_compat.py:23: UserWarning: You are using pyarrow version 11.0.0 which is known to be insecure. See https://www.cve.org/CVERecord?id=CVE-2023-47248 for further details. Please upgrade to pyarrow>=14.0.1 or install pyarrow-hotfix to patch your current version.
  warnings.warn(
WARNING:jax._src.xla_bridge:No GPU/TPU found, falling back to CPU. (Set TF_CPP_MIN_LOG_LEVEL=0 and rerun for more info.)
