Traceback (most recent call last):
  File "/home/aih/sebastian.birk/miniconda3/envs/nichecompass-test/lib/python3.9/site-packages/pandas/core/indexes/base.py", line 3802, in get_loc
    return self._engine.get_loc(casted_key)
  File "pandas/_libs/index.pyx", line 138, in pandas._libs.index.IndexEngine.get_loc
  File "pandas/_libs/index.pyx", line 165, in pandas._libs.index.IndexEngine.get_loc
  File "pandas/_libs/hashtable_class_helper.pxi", line 5745, in pandas._libs.hashtable.PyObjectHashTable.get_item
  File "pandas/_libs/hashtable_class_helper.pxi", line 5753, in pandas._libs.hashtable.PyObjectHashTable.get_item
KeyError: 'patient'

The above exception was the direct cause of the following exception:

Traceback (most recent call last):
  File "/home/aih/sebastian.birk/workspace/projects/nichecompass-reproducibility/scripts/reference/../train_nichecompass_reference_model.py", line 896, in <module>
    model = NicheCompass(adata,
  File "/home/aih/sebastian.birk/workspace/projects/nichecompass/nichecompass/models/nichecompass.py", line 448, in __init__
    self.cat_covariates_cats_ = [
  File "/home/aih/sebastian.birk/workspace/projects/nichecompass/nichecompass/models/nichecompass.py", line 449, in <listcomp>
    adata.obs[cat_covariate_key].unique().tolist() 
  File "/home/aih/sebastian.birk/miniconda3/envs/nichecompass-test/lib/python3.9/site-packages/pandas/core/frame.py", line 3807, in __getitem__
    indexer = self.columns.get_loc(key)
  File "/home/aih/sebastian.birk/miniconda3/envs/nichecompass-test/lib/python3.9/site-packages/pandas/core/indexes/base.py", line 3804, in get_loc
    raise KeyError(key) from err
KeyError: 'patient'
