Traceback (most recent call last):
  File "/lustre/groups/imm01/workspace/irene.bonafonte/Projects/2023May_nichecompass/nichecompass-reproducibility/scripts/reference_query/../nsclc_integration_metrics.py", line 22, in <module>
    adata = sc.read_h5ad(f'/lustre/groups/imm01/workspace/irene.bonafonte/Projects/2023May_nichecompass/nichecompass-reproducibility/artifacts/{dataset}/models/{model_type}/{model_label}/{dataset}_{model_type}.h5ad')
  File "/home/icb/irene.bonafonte/miniconda3/envs/nichecompass/lib/python3.9/site-packages/anndata/_io/h5ad.py", line 219, in read_h5ad
    with h5py.File(filename, "r") as f:
  File "/home/icb/irene.bonafonte/miniconda3/envs/nichecompass/lib/python3.9/site-packages/h5py/_hl/files.py", line 567, in __init__
    fid = make_fid(name, mode, userblock_size, fapl, fcpl, swmr=swmr)
  File "/home/icb/irene.bonafonte/miniconda3/envs/nichecompass/lib/python3.9/site-packages/h5py/_hl/files.py", line 231, in make_fid
    fid = h5f.open(name, flags, fapl=fapl)
  File "h5py/_objects.pyx", line 54, in h5py._objects.with_phil.wrapper
  File "h5py/_objects.pyx", line 55, in h5py._objects.with_phil.wrapper
  File "h5py/h5f.pyx", line 106, in h5py.h5f.open
FileNotFoundError: [Errno 2] Unable to open file (unable to open file: name = '/lustre/groups/imm01/workspace/irene.bonafonte/Projects/2023May_nichecompass/nichecompass-reproducibility/artifacts/nanostring_cosmx_human_nsclc/models/reference_query/19102023_172844_43_3/nanostring_cosmx_human_nsclc_reference_query.h5ad', errno = 2, error message = 'No such file or directory', flags = 0, o_flags = 0)
