WARNING:root:Failed to download from `https://omnipathdb.org/`.
WARNING:root:Traceback (most recent call last):
  File "/home/aih/sebastian.birk/miniconda3/envs/nichecompass/lib/python3.9/site-packages/urllib3/connectionpool.py", line 715, in urlopen
    httplib_response = self._make_request(
  File "/home/aih/sebastian.birk/miniconda3/envs/nichecompass/lib/python3.9/site-packages/urllib3/connectionpool.py", line 404, in _make_request
    self._validate_conn(conn)
  File "/home/aih/sebastian.birk/miniconda3/envs/nichecompass/lib/python3.9/site-packages/urllib3/connectionpool.py", line 1058, in _validate_conn
    conn.connect()
  File "/home/aih/sebastian.birk/miniconda3/envs/nichecompass/lib/python3.9/site-packages/urllib3/connection.py", line 419, in connect
    self.sock = ssl_wrap_socket(
  File "/home/aih/sebastian.birk/miniconda3/envs/nichecompass/lib/python3.9/site-packages/urllib3/util/ssl_.py", line 449, in ssl_wrap_socket
    ssl_sock = _ssl_wrap_socket_impl(
  File "/home/aih/sebastian.birk/miniconda3/envs/nichecompass/lib/python3.9/site-packages/urllib3/util/ssl_.py", line 493, in _ssl_wrap_socket_impl
    return ssl_context.wrap_socket(sock, server_hostname=server_hostname)
  File "/home/aih/sebastian.birk/miniconda3/envs/nichecompass/lib/python3.9/ssl.py", line 501, in wrap_socket
    return self.sslsocket_class._create(
  File "/home/aih/sebastian.birk/miniconda3/envs/nichecompass/lib/python3.9/ssl.py", line 1041, in _create
    self.do_handshake()
  File "/home/aih/sebastian.birk/miniconda3/envs/nichecompass/lib/python3.9/ssl.py", line 1310, in do_handshake
    self._sslobj.do_handshake()
ssl.SSLEOFError: EOF occurred in violation of protocol (_ssl.c:1129)

During handling of the above exception, another exception occurred:

Traceback (most recent call last):
  File "/home/aih/sebastian.birk/miniconda3/envs/nichecompass/lib/python3.9/site-packages/requests/adapters.py", line 486, in send
    resp = conn.urlopen(
  File "/home/aih/sebastian.birk/miniconda3/envs/nichecompass/lib/python3.9/site-packages/urllib3/connectionpool.py", line 799, in urlopen
    retries = retries.increment(
  File "/home/aih/sebastian.birk/miniconda3/envs/nichecompass/lib/python3.9/site-packages/urllib3/util/retry.py", line 592, in increment
    raise MaxRetryError(_pool, url, error or ResponseError(cause))
urllib3.exceptions.MaxRetryError: HTTPSConnectionPool(host='omnipathdb.org', port=443): Max retries exceeded with url: /queries/enzsub?format=json (Caused by SSLError(SSLEOFError(8, 'EOF occurred in violation of protocol (_ssl.c:1129)')))

During handling of the above exception, another exception occurred:

Traceback (most recent call last):
  File "/home/aih/sebastian.birk/miniconda3/envs/nichecompass/lib/python3.9/site-packages/omnipath/_core/downloader/_downloader.py", line 143, in maybe_download
    res = self._download(req)
  File "/home/aih/sebastian.birk/miniconda3/envs/nichecompass/lib/python3.9/site-packages/omnipath/_core/downloader/_downloader.py", line 178, in _download
    with self._session.send(
  File "/home/aih/sebastian.birk/miniconda3/envs/nichecompass/lib/python3.9/site-packages/requests/sessions.py", line 703, in send
    r = adapter.send(request, **kwargs)
  File "/home/aih/sebastian.birk/miniconda3/envs/nichecompass/lib/python3.9/site-packages/requests/adapters.py", line 517, in send
    raise SSLError(e, request=request)
requests.exceptions.SSLError: HTTPSConnectionPool(host='omnipathdb.org', port=443): Max retries exceeded with url: /queries/enzsub?format=json (Caused by SSLError(SSLEOFError(8, 'EOF occurred in violation of protocol (_ssl.c:1129)')))

WARNING:jax._src.xla_bridge:No GPU/TPU found, falling back to CPU. (Set TF_CPP_MIN_LOG_LEVEL=0 and rerun for more info.)
