WARNING:root:Failed to download from `https://omnipathdb.org/`.
WARNING:root:Traceback (most recent call last):
  File "/home/aih/sebastian.birk/miniconda3/envs/nichecompass-reproducibility/lib/python3.9/site-packages/urllib3/connection.py", line 174, in _new_conn
    conn = connection.create_connection(
  File "/home/aih/sebastian.birk/miniconda3/envs/nichecompass-reproducibility/lib/python3.9/site-packages/urllib3/util/connection.py", line 95, in create_connection
    raise err
  File "/home/aih/sebastian.birk/miniconda3/envs/nichecompass-reproducibility/lib/python3.9/site-packages/urllib3/util/connection.py", line 85, in create_connection
    sock.connect(sa)
socket.timeout: timed out

During handling of the above exception, another exception occurred:

Traceback (most recent call last):
  File "/home/aih/sebastian.birk/miniconda3/envs/nichecompass-reproducibility/lib/python3.9/site-packages/urllib3/connectionpool.py", line 715, in urlopen
    httplib_response = self._make_request(
  File "/home/aih/sebastian.birk/miniconda3/envs/nichecompass-reproducibility/lib/python3.9/site-packages/urllib3/connectionpool.py", line 404, in _make_request
    self._validate_conn(conn)
  File "/home/aih/sebastian.birk/miniconda3/envs/nichecompass-reproducibility/lib/python3.9/site-packages/urllib3/connectionpool.py", line 1060, in _validate_conn
    conn.connect()
  File "/home/aih/sebastian.birk/miniconda3/envs/nichecompass-reproducibility/lib/python3.9/site-packages/urllib3/connection.py", line 363, in connect
    self.sock = conn = self._new_conn()
  File "/home/aih/sebastian.birk/miniconda3/envs/nichecompass-reproducibility/lib/python3.9/site-packages/urllib3/connection.py", line 179, in _new_conn
    raise ConnectTimeoutError(
urllib3.exceptions.ConnectTimeoutError: (<urllib3.connection.HTTPSConnection object at 0x7fd8bf3c01f0>, 'Connection to omnipathdb.org timed out. (connect timeout=3.0)')

During handling of the above exception, another exception occurred:

Traceback (most recent call last):
  File "/home/aih/sebastian.birk/miniconda3/envs/nichecompass-reproducibility/lib/python3.9/site-packages/requests/adapters.py", line 667, in send
    resp = conn.urlopen(
  File "/home/aih/sebastian.birk/miniconda3/envs/nichecompass-reproducibility/lib/python3.9/site-packages/urllib3/connectionpool.py", line 801, in urlopen
    retries = retries.increment(
  File "/home/aih/sebastian.birk/miniconda3/envs/nichecompass-reproducibility/lib/python3.9/site-packages/urllib3/util/retry.py", line 594, in increment
    raise MaxRetryError(_pool, url, error or ResponseError(cause))
urllib3.exceptions.MaxRetryError: HTTPSConnectionPool(host='omnipathdb.org', port=443): Max retries exceeded with url: /queries/intercell?format=json (Caused by ConnectTimeoutError(<urllib3.connection.HTTPSConnection object at 0x7fd8bf3c01f0>, 'Connection to omnipathdb.org timed out. (connect timeout=3.0)'))

During handling of the above exception, another exception occurred:

Traceback (most recent call last):
  File "/home/aih/sebastian.birk/miniconda3/envs/nichecompass-reproducibility/lib/python3.9/site-packages/omnipath/_core/downloader/_downloader.py", line 143, in maybe_download
    res = self._download(req)
  File "/home/aih/sebastian.birk/miniconda3/envs/nichecompass-reproducibility/lib/python3.9/site-packages/omnipath/_core/downloader/_downloader.py", line 178, in _download
    with self._session.send(
  File "/home/aih/sebastian.birk/miniconda3/envs/nichecompass-reproducibility/lib/python3.9/site-packages/requests/sessions.py", line 703, in send
    r = adapter.send(request, **kwargs)
  File "/home/aih/sebastian.birk/miniconda3/envs/nichecompass-reproducibility/lib/python3.9/site-packages/requests/adapters.py", line 688, in send
    raise ConnectTimeout(e, request=request)
requests.exceptions.ConnectTimeout: HTTPSConnectionPool(host='omnipathdb.org', port=443): Max retries exceeded with url: /queries/intercell?format=json (Caused by ConnectTimeoutError(<urllib3.connection.HTTPSConnection object at 0x7fd8bf3c01f0>, 'Connection to omnipathdb.org timed out. (connect timeout=3.0)'))

WARNING:root:Malformed experiment '1'. Detailed error Yaml file '/ictstr01/home/aih/sebastian.birk/workspace/projects/nichecompass-reproducibility/analysis/data_analysis/reference/mlruns/1/meta.yaml' does not exist.
Traceback (most recent call last):
  File "/home/aih/sebastian.birk/miniconda3/envs/nichecompass-reproducibility/lib/python3.9/site-packages/mlflow/store/tracking/file_store.py", line 317, in search_experiments
    exp = self._get_experiment(exp_id, view_type)
  File "/home/aih/sebastian.birk/miniconda3/envs/nichecompass-reproducibility/lib/python3.9/site-packages/mlflow/store/tracking/file_store.py", line 410, in _get_experiment
    meta = FileStore._read_yaml(experiment_dir, FileStore.META_DATA_FILE_NAME)
  File "/home/aih/sebastian.birk/miniconda3/envs/nichecompass-reproducibility/lib/python3.9/site-packages/mlflow/store/tracking/file_store.py", line 1341, in _read_yaml
    return _read_helper(root, file_name, attempts_remaining=retries)
  File "/home/aih/sebastian.birk/miniconda3/envs/nichecompass-reproducibility/lib/python3.9/site-packages/mlflow/store/tracking/file_store.py", line 1334, in _read_helper
    result = read_yaml(root, file_name)
  File "/home/aih/sebastian.birk/miniconda3/envs/nichecompass-reproducibility/lib/python3.9/site-packages/mlflow/utils/file_utils.py", line 312, in read_yaml
    raise MissingConfigException(f"Yaml file '{file_path}' does not exist.")
mlflow.exceptions.MissingConfigException: Yaml file '/ictstr01/home/aih/sebastian.birk/workspace/projects/nichecompass-reproducibility/analysis/data_analysis/reference/mlruns/1/meta.yaml' does not exist.
WARNING:root:Malformed experiment '2'. Detailed error Yaml file '/ictstr01/home/aih/sebastian.birk/workspace/projects/nichecompass-reproducibility/analysis/data_analysis/reference/mlruns/2/meta.yaml' does not exist.
Traceback (most recent call last):
  File "/home/aih/sebastian.birk/miniconda3/envs/nichecompass-reproducibility/lib/python3.9/site-packages/mlflow/store/tracking/file_store.py", line 317, in search_experiments
    exp = self._get_experiment(exp_id, view_type)
  File "/home/aih/sebastian.birk/miniconda3/envs/nichecompass-reproducibility/lib/python3.9/site-packages/mlflow/store/tracking/file_store.py", line 410, in _get_experiment
    meta = FileStore._read_yaml(experiment_dir, FileStore.META_DATA_FILE_NAME)
  File "/home/aih/sebastian.birk/miniconda3/envs/nichecompass-reproducibility/lib/python3.9/site-packages/mlflow/store/tracking/file_store.py", line 1341, in _read_yaml
    return _read_helper(root, file_name, attempts_remaining=retries)
  File "/home/aih/sebastian.birk/miniconda3/envs/nichecompass-reproducibility/lib/python3.9/site-packages/mlflow/store/tracking/file_store.py", line 1334, in _read_helper
    result = read_yaml(root, file_name)
  File "/home/aih/sebastian.birk/miniconda3/envs/nichecompass-reproducibility/lib/python3.9/site-packages/mlflow/utils/file_utils.py", line 312, in read_yaml
    raise MissingConfigException(f"Yaml file '{file_path}' does not exist.")
mlflow.exceptions.MissingConfigException: Yaml file '/ictstr01/home/aih/sebastian.birk/workspace/projects/nichecompass-reproducibility/analysis/data_analysis/reference/mlruns/2/meta.yaml' does not exist.
/ictstr01/home/aih/sebastian.birk/workspace/projects/nichecompass/src/nichecompass/utils/gene_programs.py:203: ImplicitModificationWarning: Trying to modify attribute `._uns` of view, initializing view as actual.
  adata.uns[sources_categories_label_encoder_key] = sources_categories_label_encoder
/home/aih/sebastian.birk/miniconda3/envs/nichecompass-reproducibility/lib/python3.9/site-packages/torch_geometric/sampler/neighbor_sampler.py:55: UserWarning: The usage of the 'directed' argument in 'NeighborSampler' is deprecated. Use `subgraph_type='induced'` instead.
  warnings.warn(f"The usage of the 'directed' argument in "
Traceback (most recent call last):
  File "/ictstr01/home/aih/sebastian.birk/workspace/projects/nichecompass-reproducibility/analysis/data_analysis/reference/../train_nichecompass_reference_model.py", line 1006, in <module>
    model.train(n_epochs=args.n_epochs,
  File "/ictstr01/home/aih/sebastian.birk/workspace/projects/nichecompass/src/nichecompass/models/nichecompass.py", line 774, in train
    self.trainer.train(
  File "/ictstr01/home/aih/sebastian.birk/workspace/projects/nichecompass/src/nichecompass/train/trainer.py", line 490, in train
    self.eval_end()
  File "/home/aih/sebastian.birk/miniconda3/envs/nichecompass-reproducibility/lib/python3.9/site-packages/torch/utils/_contextlib.py", line 115, in decorate_context
    return func(*args, **kwargs)
  File "/ictstr01/home/aih/sebastian.birk/workspace/projects/nichecompass/src/nichecompass/train/trainer.py", line 660, in eval_end
    val_eval_dict = eval_metrics(
  File "/ictstr01/home/aih/sebastian.birk/workspace/projects/nichecompass/src/nichecompass/train/metrics.py", line 74, in eval_metrics
    eval_dict["source_rna_mse_score"] = skm.mean_squared_error(
  File "/home/aih/sebastian.birk/miniconda3/envs/nichecompass-reproducibility/lib/python3.9/site-packages/sklearn/utils/_param_validation.py", line 213, in wrapper
    return func(*args, **kwargs)
  File "/home/aih/sebastian.birk/miniconda3/envs/nichecompass-reproducibility/lib/python3.9/site-packages/sklearn/metrics/_regression.py", line 506, in mean_squared_error
    y_type, y_true, y_pred, multioutput = _check_reg_targets(
  File "/home/aih/sebastian.birk/miniconda3/envs/nichecompass-reproducibility/lib/python3.9/site-packages/sklearn/metrics/_regression.py", line 112, in _check_reg_targets
    y_true = check_array(y_true, ensure_2d=False, dtype=dtype)
  File "/home/aih/sebastian.birk/miniconda3/envs/nichecompass-reproducibility/lib/python3.9/site-packages/sklearn/utils/validation.py", line 1087, in check_array
    raise ValueError(
ValueError: Found array with 0 sample(s) (shape=(0,)) while a minimum of 1 is required.
