WARNING:root:Failed to download from `https://omnipathdb.org/`.
WARNING:root:Traceback (most recent call last):
  File "/home/aih/sebastian.birk/miniconda3/envs/nichecompass-reproducibility/lib/python3.9/site-packages/urllib3/connectionpool.py", line 715, in urlopen
    httplib_response = self._make_request(
  File "/home/aih/sebastian.birk/miniconda3/envs/nichecompass-reproducibility/lib/python3.9/site-packages/urllib3/connectionpool.py", line 404, in _make_request
    self._validate_conn(conn)
  File "/home/aih/sebastian.birk/miniconda3/envs/nichecompass-reproducibility/lib/python3.9/site-packages/urllib3/connectionpool.py", line 1060, in _validate_conn
    conn.connect()
  File "/home/aih/sebastian.birk/miniconda3/envs/nichecompass-reproducibility/lib/python3.9/site-packages/urllib3/connection.py", line 419, in connect
    self.sock = ssl_wrap_socket(
  File "/home/aih/sebastian.birk/miniconda3/envs/nichecompass-reproducibility/lib/python3.9/site-packages/urllib3/util/ssl_.py", line 449, in ssl_wrap_socket
    ssl_sock = _ssl_wrap_socket_impl(
  File "/home/aih/sebastian.birk/miniconda3/envs/nichecompass-reproducibility/lib/python3.9/site-packages/urllib3/util/ssl_.py", line 493, in _ssl_wrap_socket_impl
    return ssl_context.wrap_socket(sock, server_hostname=server_hostname)
  File "/home/aih/sebastian.birk/miniconda3/envs/nichecompass-reproducibility/lib/python3.9/ssl.py", line 501, in wrap_socket
    return self.sslsocket_class._create(
  File "/home/aih/sebastian.birk/miniconda3/envs/nichecompass-reproducibility/lib/python3.9/ssl.py", line 1074, in _create
    self.do_handshake()
  File "/home/aih/sebastian.birk/miniconda3/envs/nichecompass-reproducibility/lib/python3.9/ssl.py", line 1343, in do_handshake
    self._sslobj.do_handshake()
ssl.SSLZeroReturnError: TLS/SSL connection has been closed (EOF) (_ssl.c:1133)

During handling of the above exception, another exception occurred:

Traceback (most recent call last):
  File "/home/aih/sebastian.birk/miniconda3/envs/nichecompass-reproducibility/lib/python3.9/site-packages/requests/adapters.py", line 667, in send
    resp = conn.urlopen(
  File "/home/aih/sebastian.birk/miniconda3/envs/nichecompass-reproducibility/lib/python3.9/site-packages/urllib3/connectionpool.py", line 801, in urlopen
    retries = retries.increment(
  File "/home/aih/sebastian.birk/miniconda3/envs/nichecompass-reproducibility/lib/python3.9/site-packages/urllib3/util/retry.py", line 594, in increment
    raise MaxRetryError(_pool, url, error or ResponseError(cause))
urllib3.exceptions.MaxRetryError: HTTPSConnectionPool(host='omnipathdb.org', port=443): Max retries exceeded with url: /queries/enzsub?format=json (Caused by SSLError(SSLZeroReturnError(6, 'TLS/SSL connection has been closed (EOF) (_ssl.c:1133)')))

During handling of the above exception, another exception occurred:

Traceback (most recent call last):
  File "/home/aih/sebastian.birk/miniconda3/envs/nichecompass-reproducibility/lib/python3.9/site-packages/omnipath/_core/downloader/_downloader.py", line 143, in maybe_download
    res = self._download(req)
  File "/home/aih/sebastian.birk/miniconda3/envs/nichecompass-reproducibility/lib/python3.9/site-packages/omnipath/_core/downloader/_downloader.py", line 178, in _download
    with self._session.send(
  File "/home/aih/sebastian.birk/miniconda3/envs/nichecompass-reproducibility/lib/python3.9/site-packages/requests/sessions.py", line 703, in send
    r = adapter.send(request, **kwargs)
  File "/home/aih/sebastian.birk/miniconda3/envs/nichecompass-reproducibility/lib/python3.9/site-packages/requests/adapters.py", line 698, in send
    raise SSLError(e, request=request)
requests.exceptions.SSLError: HTTPSConnectionPool(host='omnipathdb.org', port=443): Max retries exceeded with url: /queries/enzsub?format=json (Caused by SSLError(SSLZeroReturnError(6, 'TLS/SSL connection has been closed (EOF) (_ssl.c:1133)')))

WARNING:root:Malformed experiment '1'. Detailed error Yaml file '/ictstr01/home/aih/sebastian.birk/workspace/projects/nichecompass-reproducibility/analysis/data_analysis/reference/mlruns/1/meta.yaml' does not exist.
Traceback (most recent call last):
  File "/home/aih/sebastian.birk/miniconda3/envs/nichecompass-reproducibility/lib/python3.9/site-packages/mlflow/store/tracking/file_store.py", line 317, in search_experiments
    exp = self._get_experiment(exp_id, view_type)
  File "/home/aih/sebastian.birk/miniconda3/envs/nichecompass-reproducibility/lib/python3.9/site-packages/mlflow/store/tracking/file_store.py", line 410, in _get_experiment
    meta = FileStore._read_yaml(experiment_dir, FileStore.META_DATA_FILE_NAME)
  File "/home/aih/sebastian.birk/miniconda3/envs/nichecompass-reproducibility/lib/python3.9/site-packages/mlflow/store/tracking/file_store.py", line 1341, in _read_yaml
    return _read_helper(root, file_name, attempts_remaining=retries)
  File "/home/aih/sebastian.birk/miniconda3/envs/nichecompass-reproducibility/lib/python3.9/site-packages/mlflow/store/tracking/file_store.py", line 1334, in _read_helper
    result = read_yaml(root, file_name)
  File "/home/aih/sebastian.birk/miniconda3/envs/nichecompass-reproducibility/lib/python3.9/site-packages/mlflow/utils/file_utils.py", line 312, in read_yaml
    raise MissingConfigException(f"Yaml file '{file_path}' does not exist.")
mlflow.exceptions.MissingConfigException: Yaml file '/ictstr01/home/aih/sebastian.birk/workspace/projects/nichecompass-reproducibility/analysis/data_analysis/reference/mlruns/1/meta.yaml' does not exist.
WARNING:root:Malformed experiment '2'. Detailed error Yaml file '/ictstr01/home/aih/sebastian.birk/workspace/projects/nichecompass-reproducibility/analysis/data_analysis/reference/mlruns/2/meta.yaml' does not exist.
Traceback (most recent call last):
  File "/home/aih/sebastian.birk/miniconda3/envs/nichecompass-reproducibility/lib/python3.9/site-packages/mlflow/store/tracking/file_store.py", line 317, in search_experiments
    exp = self._get_experiment(exp_id, view_type)
  File "/home/aih/sebastian.birk/miniconda3/envs/nichecompass-reproducibility/lib/python3.9/site-packages/mlflow/store/tracking/file_store.py", line 410, in _get_experiment
    meta = FileStore._read_yaml(experiment_dir, FileStore.META_DATA_FILE_NAME)
  File "/home/aih/sebastian.birk/miniconda3/envs/nichecompass-reproducibility/lib/python3.9/site-packages/mlflow/store/tracking/file_store.py", line 1341, in _read_yaml
    return _read_helper(root, file_name, attempts_remaining=retries)
  File "/home/aih/sebastian.birk/miniconda3/envs/nichecompass-reproducibility/lib/python3.9/site-packages/mlflow/store/tracking/file_store.py", line 1334, in _read_helper
    result = read_yaml(root, file_name)
  File "/home/aih/sebastian.birk/miniconda3/envs/nichecompass-reproducibility/lib/python3.9/site-packages/mlflow/utils/file_utils.py", line 312, in read_yaml
    raise MissingConfigException(f"Yaml file '{file_path}' does not exist.")
mlflow.exceptions.MissingConfigException: Yaml file '/ictstr01/home/aih/sebastian.birk/workspace/projects/nichecompass-reproducibility/analysis/data_analysis/reference/mlruns/2/meta.yaml' does not exist.
2024/08/08 14:00:45 INFO mlflow.tracking.fluent: Experiment with name 'seqfish_mouse_organogenesis_imputed_subsample_1pct_reference' does not exist. Creating a new experiment.
WARNING:root:Malformed experiment '1'. Detailed error Yaml file '/ictstr01/home/aih/sebastian.birk/workspace/projects/nichecompass-reproducibility/analysis/data_analysis/reference/mlruns/1/meta.yaml' does not exist.
Traceback (most recent call last):
  File "/home/aih/sebastian.birk/miniconda3/envs/nichecompass-reproducibility/lib/python3.9/site-packages/mlflow/store/tracking/file_store.py", line 317, in search_experiments
    exp = self._get_experiment(exp_id, view_type)
  File "/home/aih/sebastian.birk/miniconda3/envs/nichecompass-reproducibility/lib/python3.9/site-packages/mlflow/store/tracking/file_store.py", line 410, in _get_experiment
    meta = FileStore._read_yaml(experiment_dir, FileStore.META_DATA_FILE_NAME)
  File "/home/aih/sebastian.birk/miniconda3/envs/nichecompass-reproducibility/lib/python3.9/site-packages/mlflow/store/tracking/file_store.py", line 1341, in _read_yaml
    return _read_helper(root, file_name, attempts_remaining=retries)
  File "/home/aih/sebastian.birk/miniconda3/envs/nichecompass-reproducibility/lib/python3.9/site-packages/mlflow/store/tracking/file_store.py", line 1334, in _read_helper
    result = read_yaml(root, file_name)
  File "/home/aih/sebastian.birk/miniconda3/envs/nichecompass-reproducibility/lib/python3.9/site-packages/mlflow/utils/file_utils.py", line 312, in read_yaml
    raise MissingConfigException(f"Yaml file '{file_path}' does not exist.")
mlflow.exceptions.MissingConfigException: Yaml file '/ictstr01/home/aih/sebastian.birk/workspace/projects/nichecompass-reproducibility/analysis/data_analysis/reference/mlruns/1/meta.yaml' does not exist.
WARNING:root:Malformed experiment '2'. Detailed error Yaml file '/ictstr01/home/aih/sebastian.birk/workspace/projects/nichecompass-reproducibility/analysis/data_analysis/reference/mlruns/2/meta.yaml' does not exist.
Traceback (most recent call last):
  File "/home/aih/sebastian.birk/miniconda3/envs/nichecompass-reproducibility/lib/python3.9/site-packages/mlflow/store/tracking/file_store.py", line 317, in search_experiments
    exp = self._get_experiment(exp_id, view_type)
  File "/home/aih/sebastian.birk/miniconda3/envs/nichecompass-reproducibility/lib/python3.9/site-packages/mlflow/store/tracking/file_store.py", line 410, in _get_experiment
    meta = FileStore._read_yaml(experiment_dir, FileStore.META_DATA_FILE_NAME)
  File "/home/aih/sebastian.birk/miniconda3/envs/nichecompass-reproducibility/lib/python3.9/site-packages/mlflow/store/tracking/file_store.py", line 1341, in _read_yaml
    return _read_helper(root, file_name, attempts_remaining=retries)
  File "/home/aih/sebastian.birk/miniconda3/envs/nichecompass-reproducibility/lib/python3.9/site-packages/mlflow/store/tracking/file_store.py", line 1334, in _read_helper
    result = read_yaml(root, file_name)
  File "/home/aih/sebastian.birk/miniconda3/envs/nichecompass-reproducibility/lib/python3.9/site-packages/mlflow/utils/file_utils.py", line 312, in read_yaml
    raise MissingConfigException(f"Yaml file '{file_path}' does not exist.")
mlflow.exceptions.MissingConfigException: Yaml file '/ictstr01/home/aih/sebastian.birk/workspace/projects/nichecompass-reproducibility/analysis/data_analysis/reference/mlruns/2/meta.yaml' does not exist.
/ictstr01/home/aih/sebastian.birk/workspace/projects/nichecompass/src/nichecompass/utils/gene_programs.py:506: FutureWarning: DataFrame.applymap has been deprecated. Use DataFrame.map instead.
  ligand_target_matrix_df.applymap(
/home/aih/sebastian.birk/miniconda3/envs/nichecompass-reproducibility/lib/python3.9/site-packages/scanpy/metrics/_gearys_c.py:295: UserWarning: 21819 variables were constant, will return nan for these.
  warnings.warn(
/ictstr01/home/aih/sebastian.birk/workspace/projects/nichecompass/src/nichecompass/utils/gene_programs.py:203: ImplicitModificationWarning: Trying to modify attribute `._uns` of view, initializing view as actual.
  adata.uns[sources_categories_label_encoder_key] = sources_categories_label_encoder
/home/aih/sebastian.birk/miniconda3/envs/nichecompass-reproducibility/lib/python3.9/site-packages/torch/cuda/__init__.py:173: UserWarning: 
NVIDIA H100 80GB HBM3 with CUDA capability sm_90 is not compatible with the current PyTorch installation.
The current PyTorch install supports CUDA capabilities sm_37 sm_50 sm_60 sm_61 sm_70 sm_75 sm_80 sm_86 compute_37.
If you want to use the NVIDIA H100 80GB HBM3 GPU with PyTorch, please check the instructions at https://pytorch.org/get-started/locally/

  warnings.warn(incompatible_device_warn.format(device_name, capability, " ".join(arch_list), device_name))
/home/aih/sebastian.birk/miniconda3/envs/nichecompass-reproducibility/lib/python3.9/site-packages/torch_geometric/sampler/neighbor_sampler.py:55: UserWarning: The usage of the 'directed' argument in 'NeighborSampler' is deprecated. Use `subgraph_type='induced'` instead.
  warnings.warn(f"The usage of the 'directed' argument in "
/home/aih/sebastian.birk/miniconda3/envs/nichecompass-reproducibility/lib/python3.9/site-packages/torch_geometric/sampler/neighbor_sampler.py:55: UserWarning: The usage of the 'directed' argument in 'NeighborSampler' is deprecated. Use `subgraph_type='induced'` instead.
  warnings.warn(f"The usage of the 'directed' argument in "
/home/aih/sebastian.birk/miniconda3/envs/nichecompass-reproducibility/lib/python3.9/site-packages/sklearn/manifold/_spectral_embedding.py:329: UserWarning: Graph is not fully connected, spectral embedding may not work as expected.
  warnings.warn(
